0 ============================================================
Traceback (most recent call last):
  File "/glade/work/zilumeng/3D_trans/./mul_train/check_error.py", line 77, in <module>
    plt.savefig(f"../data/noise1/pic/3x4p_1_{model_idx}.png")
  File "/glade/work/zilumeng/conda-envs/earth2mip/lib/python3.10/site-packages/matplotlib/pyplot.py", line 1119, in savefig
    res = fig.savefig(*args, **kwargs)  # type: ignore[func-returns-value]
  File "/glade/work/zilumeng/conda-envs/earth2mip/lib/python3.10/site-packages/matplotlib/figure.py", line 3390, in savefig
    self.canvas.print_figure(fname, **kwargs)
  File "/glade/work/zilumeng/conda-envs/earth2mip/lib/python3.10/site-packages/matplotlib/backend_bases.py", line 2187, in print_figure
    result = print_method(
  File "/glade/work/zilumeng/conda-envs/earth2mip/lib/python3.10/site-packages/matplotlib/backend_bases.py", line 2043, in <lambda>
    print_method = functools.wraps(meth)(lambda *args, **kwargs: meth(
  File "/glade/work/zilumeng/conda-envs/earth2mip/lib/python3.10/site-packages/matplotlib/backends/backend_agg.py", line 497, in print_png
    self._print_pil(filename_or_obj, "png", pil_kwargs, metadata)
  File "/glade/work/zilumeng/conda-envs/earth2mip/lib/python3.10/site-packages/matplotlib/backends/backend_agg.py", line 446, in _print_pil
    mpl.image.imsave(
  File "/glade/work/zilumeng/conda-envs/earth2mip/lib/python3.10/site-packages/matplotlib/image.py", line 1656, in imsave
    image.save(fname, **pil_kwargs)
  File "/glade/work/zilumeng/conda-envs/earth2mip/lib/python3.10/site-packages/PIL/Image.py", line 2410, in save
    fp = builtins.open(filename, "w+b")
FileNotFoundError: [Errno 2] No such file or directory: '../data/noise1/pic/3x4p_1_0.png'
